package corejava.exception.demo;

public class ExceptionDemo {

	public void dummy(){}
	
	public static void main(String[] args) {
	
		try{
			
			int x=2/0;
			
			try{
				ExceptionDemo d=null;
				d.dummy();
			}
			catch(ArithmeticException e){
				System.out.println("Nested catch");
			}
			
		}
		catch(ArithmeticException e){
			e.printStackTrace();
		}
		catch(Throwable e){
			System.out.println("In outer catch");
			//e.printStackTrace();
		}
		finally{
			System.out.println("In finally");
		}
	}

}
